<sdf version='1.11'>
  <model name='physicar'>
    <link name='base_footprint'>
      <inertial>
        <pose>-0.00087096774193548391 0 0.024741935483870958 0 0 0</pose>
        <mass>3.1000000000000001</mass>
        <inertia>
          <ixx>0.0080554435483870968</ixx>
          <ixy>0</ixy>
          <ixz>0.00042459677419354842</ixz>
          <iyy>0.027925991935483872</iyy>
          <iyz>0</iyz>
          <izz>0.025370548387096771</izz>
        </inertia>
      </inertial>
      <collision name='base_footprint_fixed_joint_lump__base_collision_collision'>
        <pose>0 0 0.079500000000000002 0 0 0</pose>
        <geometry>
          <box>
            <size>0.27000000000000002 0.089999999999999997 0.12</size>
          </box>
        </geometry>
      </collision>
      <collision name='base_footprint_fixed_joint_lump__lidar_collision_collision_1'>
        <pose>-0.027 0 0.18200000000000001 0 0 0</pose>
        <geometry>
          <cylinder>
            <length>0.040000000000000001</length>
            <radius>0.035000000000000003</radius>
          </cylinder>
        </geometry>
      </collision>
      <visual name='base_footprint_fixed_joint_lump__base_visual_visual'>
        <pose>0 0 0.041499999999999998 0 0 0</pose>
        <geometry>
          <mesh>
            <scale>1 1 1</scale>
            <uri>model://meshes/physicar/Base.dae</uri>
          </mesh>
        </geometry>
      </visual>
      <visual name='base_footprint_fixed_joint_lump__top_visual_visual_1'>
        <pose>0 0 0.019499999999999998 0 0 0</pose>
        <geometry>
          <mesh>
            <scale>1 1 1</scale>
            <uri>model://meshes/physicar/Body.dae</uri>
          </mesh>
        </geometry>
      </visual>
      <visual name='base_footprint_fixed_joint_lump__lidar_visual_visual_2'>
        <pose>0 0 0.019499999999999998 0 0 0</pose>
        <geometry>
          <mesh>
            <scale>1 1 1</scale>
            <uri>model://meshes/physicar/RPLidarC1.dae</uri>
          </mesh>
        </geometry>
      </visual>
      <sensor name='imu_sensor' type='imu'>
        <always_on>true</always_on>
        <update_rate>50</update_rate>
        <visualize>false</visualize>
        <topic>imu</topic>
        <imu>
          <angular_velocity>
            <x>
              <noise type='gaussian'>
                <mean>0</mean>
                <stddev>0.00020000000000000001</stddev>
              </noise>
            </x>
            <y>
              <noise type='gaussian'>
                <mean>0</mean>
                <stddev>0.00020000000000000001</stddev>
              </noise>
            </y>
            <z>
              <noise type='gaussian'>
                <mean>0</mean>
                <stddev>0.00020000000000000001</stddev>
              </noise>
            </z>
          </angular_velocity>
          <linear_acceleration>
            <x>
              <noise type='gaussian'>
                <mean>0</mean>
                <stddev>0.017000000000000001</stddev>
              </noise>
            </x>
            <y>
              <noise type='gaussian'>
                <mean>0</mean>
                <stddev>0.017000000000000001</stddev>
              </noise>
            </y>
            <z>
              <noise type='gaussian'>
                <mean>0</mean>
                <stddev>0.017000000000000001</stddev>
              </noise>
            </z>
          </linear_acceleration>
        </imu>
        <pose>0 0 0.0275 0 0 0</pose>
        <gz_frame_id>imu_link</gz_frame_id>
      </sensor>
      <sensor name='mag_sensor' type='magnetometer'>
        <always_on>true</always_on>
        <update_rate>50</update_rate>
        <visualize>false</visualize>
        <topic>mag</topic>
        <magnetometer>
          <x>
            <noise type='gaussian'>
              <mean>0</mean>
              <stddev>0.1</stddev>
            </noise>
          </x>
          <y>
            <noise type='gaussian'>
              <mean>0</mean>
              <stddev>0.1</stddev>
            </noise>
          </y>
          <z>
            <noise type='gaussian'>
              <mean>0</mean>
              <stddev>0.1</stddev>
            </noise>
          </z>
        </magnetometer>
        <pose>0 0 0.0275 0 0 0</pose>
        <gz_frame_id>imu_link</gz_frame_id>
      </sensor>
      <sensor name='lidar_sensor' type='gpu_lidar'>
        <always_on>true</always_on>
        <update_rate>10</update_rate>
        <visualize>false</visualize>
        <topic>scan</topic>
        <lidar>
          <scan>
            <horizontal>
              <samples>720</samples>
              <resolution>1</resolution>
              <min_angle>-3.1415899999999999</min_angle>
              <max_angle>3.1415899999999999</max_angle>
            </horizontal>
          </scan>
          <range>
            <min>0.10000000000000001</min>
            <max>16</max>
            <resolution>0.01</resolution>
          </range>
          <noise>
            <type>gaussian</type>
            <mean>0</mean>
            <stddev>0.01</stddev>
          </noise>
        </lidar>
        <pose>-0.027 0 0.18200000000000001 0 0 0</pose>
        <gz_frame_id>lidar_link</gz_frame_id>
      </sensor>
    </link>
    <joint name='camera_pan_joint' type='revolute'>
      <pose relative_to='base_footprint'>0.050000000000000003 0 0.11950000000000001 0 0 0</pose>
      <parent>base_footprint</parent>
      <child>camera_pan_link</child>
      <axis>
        <xyz>0 0 1</xyz>
        <limit>
          <lower>-0.7854</lower>
          <upper>0.7854</upper>
          <effort>100</effort>
          <velocity>10</velocity>
        </limit>
        <dynamics>
          <damping>0.1</damping>
          <friction>0.01</friction>
          <spring_reference>0</spring_reference>
          <spring_stiffness>0</spring_stiffness>
        </dynamics>
      </axis>
    </joint>
    <link name='camera_pan_link'>
      <pose relative_to='camera_pan_joint'>0 0 0 0 0 0</pose>
      <inertial>
        <pose>0 0 0 0 0 0</pose>
        <mass>0.02</mass>
        <inertia>
          <ixx>1.0e-04</ixx>
          <ixy>0</ixy>
          <ixz>0</ixz>
          <iyy>1.0e-04</iyy>
          <iyz>0</iyz>
          <izz>1.0e-04</izz>
        </inertia>
      </inertial>

      <visual name='camera_pan_link_fixed_joint_lump__pan_visual_visual'>
        <pose>-0.050000000000000003 0 -0.10000000000000001 0 0 0</pose>
        <geometry>
          <mesh>
            <scale>1 1 1</scale>
            <uri>model://meshes/physicar/ServoPan.dae</uri>
          </mesh>
        </geometry>
      </visual>
    </link>
    <joint name='camera_tilt_joint' type='revolute'>
      <pose relative_to='camera_pan_link'>0.025000000000000001 0 0.012999999999999999 0 0 0</pose>
      <parent>camera_pan_link</parent>
      <child>camera_tilt_link</child>
      <axis>
        <xyz>0 -1 0</xyz>
        <limit>
          <lower>-0.7854</lower>
          <upper>0.7854</upper>
          <effort>100</effort>
          <velocity>10</velocity>
        </limit>
        <dynamics>
          <damping>0.1</damping>
          <friction>0.01</friction>
          <spring_reference>0</spring_reference>
          <spring_stiffness>0</spring_stiffness>
        </dynamics>
      </axis>
    </joint>
    <link name='camera_tilt_link'>
      <pose relative_to='camera_tilt_joint'>0 0 0 0 0 0</pose>
      <inertial>
        <pose>0.0094999999999999998 0 0.0035000000000000009 0 0 0</pose>
        <mass>0.02</mass>
        <inertia>
          <ixx>1.0e-04</ixx>
          <ixy>0</ixy>
          <ixz>0</ixz>
          <iyy>1.0e-04</iyy>
          <iyz>0</iyz>
          <izz>1.0e-04</izz>
        </inertia>
      </inertial>

      <visual name='camera_tilt_link_fixed_joint_lump__tilt_visual_visual'>
        <pose>-0.074999999999999997 0 -0.113 0 0 0</pose>
        <geometry>
          <mesh>
            <scale>1 1 1</scale>
            <uri>model://meshes/physicar/ServoTilt.dae</uri>
          </mesh>
        </geometry>
      </visual>
      <sensor name='camera_sensor' type='camera'>
        <always_on>true</always_on>
        <update_rate>15</update_rate>
        <visualize>false</visualize>
        <topic>camera/image_raw</topic>
        <camera>
          <horizontal_fov>1.7453</horizontal_fov>
          <image>
            <width>480</width>
            <height>360</height>
            <format>R8G8B8</format>
          </image>
          <clip>
            <near>0.01</near>
            <far>50</far>
          </clip>
          <distortion>
            <k1>-0.045</k1>
            <k2>-0.0001</k2>
            <k3>0.001</k3>
            <p1>-0.0003</p1>
            <p2>-0.0001</p2>
            <center>0.5 0.5</center>
          </distortion>
          <noise>
            <type>gaussian</type>
            <mean>0</mean>
            <stddev>0.0070000000000000001</stddev>
          </noise>
        </camera>
        <pose>0.030 0 0.014 0 0 0</pose>
        <gz_frame_id>camera_optical_frame</gz_frame_id>
      </sensor>
    </link>
    <joint name='front_left_steering_joint' type='revolute'>
      <pose relative_to='base_footprint'>0.090000000000000000 0.080000000000000000 0.0375 0 0 0</pose>
      <parent>base_footprint</parent>
      <child>front_left_steering_link</child>
      <axis>
        <xyz>0 0 1</xyz>
        <limit>
          <lower>-0.59999999999999998</lower>
          <upper>0.59999999999999998</upper>
          <effort>25</effort>
          <velocity>100</velocity>
        </limit>
        <dynamics>
          <damping>0.0001</damping>
          <friction>0.0001</friction>
          <spring_reference>0</spring_reference>
          <spring_stiffness>0</spring_stiffness>
        </dynamics>
      </axis>
    </joint>
    <link name='front_left_steering_link'>
      <pose relative_to='front_left_steering_joint'>0 0 0 0 0 0</pose>
      <inertial>
        <pose>0 0 0 0 0 0</pose>
        <mass>0.01</mass>
        <inertia>
          <ixx>9.9999999999999995e-07</ixx>
          <ixy>0</ixy>
          <ixz>0</ixz>
          <iyy>9.9999999999999995e-07</iyy>
          <iyz>0</iyz>
          <izz>9.9999999999999995e-07</izz>
        </inertia>
      </inertial>
    </link>
    <joint name='front_left_wheel_joint' type='revolute'>
      <pose relative_to='front_left_steering_link'>0 0 0 0 0 0</pose>
      <parent>front_left_steering_link</parent>
      <child>front_left_wheel_link</child>
      <axis>
        <xyz>0 1 0</xyz>
        <limit>
          <lower>-inf</lower>
          <upper>inf</upper>
        </limit>
        <dynamics>
          <damping>0.5</damping>
          <friction>0.10000000000000001</friction>
          <spring_reference>0</spring_reference>
          <spring_stiffness>0</spring_stiffness>
        </dynamics>
      </axis>
    </joint>
    <link name='front_left_wheel_link'>
      <pose relative_to='front_left_wheel_joint'>0 0 0 0 0 0</pose>
      <inertial>
        <pose>0 0 0 0 0 0</pose>
        <mass>0.050000000000000003</mass>
        <inertia>
          <ixx>2.1757291666666671e-05</ixx>
          <ixy>0</ixy>
          <ixz>0</ixz>
          <iyy>3.330625e-05</iyy>
          <iyz>0</iyz>
          <izz>2.1757291666666671e-05</izz>
        </inertia>
      </inertial>
      <collision name='front_left_wheel_link_collision'>
        <pose>0 0 0 1.5707963267948959 0 0</pose>
        <geometry>
          <cylinder>
            <length>0.035000000000000003</length>
            <radius>0.0375</radius>
          </cylinder>
        </geometry>
        <surface>
          <contact>
            <ode>
              <kp>1000000</kp>
              <kd>100</kd>
              <min_depth>0.001</min_depth>
            </ode>
          </contact>
          <friction>
            <ode>
              <mu>1</mu>
              <mu2>1</mu2>
            </ode>
          </friction>
        </surface>
      </collision>
      <visual name='front_left_wheel_link_visual'>
        <pose>0 0.017500000000000002 0 0 0 3.1415926535897931</pose>
        <geometry>
          <mesh>
            <scale>1 1 1</scale>
            <uri>model://meshes/physicar/Wheel.dae</uri>
          </mesh>
        </geometry>
      </visual>
    </link>
    <joint name='front_right_steering_joint' type='revolute'>
      <pose relative_to='base_footprint'>0.090000000000000000 -0.080000000000000000 0.0375 0 0 0</pose>
      <parent>base_footprint</parent>
      <child>front_right_steering_link</child>
      <axis>
        <xyz>0 0 1</xyz>
        <limit>
          <lower>-0.59999999999999998</lower>
          <upper>0.59999999999999998</upper>
          <effort>25</effort>
          <velocity>100</velocity>
        </limit>
        <dynamics>
          <damping>0.0001</damping>
          <friction>0.0001</friction>
          <spring_reference>0</spring_reference>
          <spring_stiffness>0</spring_stiffness>
        </dynamics>
      </axis>
    </joint>
    <link name='front_right_steering_link'>
      <pose relative_to='front_right_steering_joint'>0 0 0 0 0 0</pose>
      <inertial>
        <pose>0 0 0 0 0 0</pose>
        <mass>0.01</mass>
        <inertia>
          <ixx>9.9999999999999995e-07</ixx>
          <ixy>0</ixy>
          <ixz>0</ixz>
          <iyy>9.9999999999999995e-07</iyy>
          <iyz>0</iyz>
          <izz>9.9999999999999995e-07</izz>
        </inertia>
      </inertial>
    </link>
    <joint name='front_right_wheel_joint' type='revolute'>
      <pose relative_to='front_right_steering_link'>0 0 0 0 0 0</pose>
      <parent>front_right_steering_link</parent>
      <child>front_right_wheel_link</child>
      <axis>
        <xyz>0 1 0</xyz>
        <limit>
          <lower>-inf</lower>
          <upper>inf</upper>
        </limit>
        <dynamics>
          <damping>0.5</damping>
          <friction>0.10000000000000001</friction>
          <spring_reference>0</spring_reference>
          <spring_stiffness>0</spring_stiffness>
        </dynamics>
      </axis>
    </joint>
    <link name='front_right_wheel_link'>
      <pose relative_to='front_right_wheel_joint'>0 0 0 0 0 0</pose>
      <inertial>
        <pose>0 0 0 0 0 0</pose>
        <mass>0.050000000000000003</mass>
        <inertia>
          <ixx>2.1757291666666671e-05</ixx>
          <ixy>0</ixy>
          <ixz>0</ixz>
          <iyy>3.330625e-05</iyy>
          <iyz>0</iyz>
          <izz>2.1757291666666671e-05</izz>
        </inertia>
      </inertial>
      <collision name='front_right_wheel_link_collision'>
        <pose>0 0 0 1.5707963267948959 0 0</pose>
        <geometry>
          <cylinder>
            <length>0.035000000000000003</length>
            <radius>0.0375</radius>
          </cylinder>
        </geometry>
        <surface>
          <contact>
            <ode>
              <kp>1000000</kp>
              <kd>100</kd>
              <min_depth>0.001</min_depth>
            </ode>
          </contact>
          <friction>
            <ode>
              <mu>1</mu>
              <mu2>1</mu2>
            </ode>
          </friction>
        </surface>
      </collision>
      <visual name='front_right_wheel_link_visual'>
        <pose>0 -0.017500000000000002 0 0 0 0</pose>
        <geometry>
          <mesh>
            <scale>1 1 1</scale>
            <uri>model://meshes/physicar/Wheel.dae</uri>
          </mesh>
        </geometry>
      </visual>
    </link>
    <joint name='rear_left_wheel_joint' type='revolute'>
      <pose relative_to='base_footprint'>-0.090000000000000000 0.080000000000000000 0.0375 0 0 0</pose>
      <parent>base_footprint</parent>
      <child>rear_left_wheel_link</child>
      <axis>
        <xyz>0 1 0</xyz>
        <limit>
          <lower>-inf</lower>
          <upper>inf</upper>
        </limit>
        <dynamics>
          <damping>0.5</damping>
          <friction>0.10000000000000001</friction>
          <spring_reference>0</spring_reference>
          <spring_stiffness>0</spring_stiffness>
        </dynamics>
      </axis>
    </joint>
    <link name='rear_left_wheel_link'>
      <pose relative_to='rear_left_wheel_joint'>0 0 0 0 0 0</pose>
      <inertial>
        <pose>0 0 0 0 0 0</pose>
        <mass>0.050000000000000003</mass>
        <inertia>
          <ixx>2.1757291666666671e-05</ixx>
          <ixy>0</ixy>
          <ixz>0</ixz>
          <iyy>3.330625e-05</iyy>
          <iyz>0</iyz>
          <izz>2.1757291666666671e-05</izz>
        </inertia>
      </inertial>
      <collision name='rear_left_wheel_link_collision'>
        <pose>0 0 0 1.5707963267948959 0 0</pose>
        <geometry>
          <cylinder>
            <length>0.035000000000000003</length>
            <radius>0.0375</radius>
          </cylinder>
        </geometry>
        <surface>
          <contact>
            <ode>
              <kp>1000000</kp>
              <kd>100</kd>
              <min_depth>0.001</min_depth>
            </ode>
          </contact>
          <friction>
            <ode>
              <mu>1</mu>
              <mu2>1</mu2>
            </ode>
          </friction>
        </surface>
      </collision>
      <visual name='rear_left_wheel_link_visual'>
        <pose>0 0.017500000000000002 0 0 0 3.1415926535897931</pose>
        <geometry>
          <mesh>
            <scale>1 1 1</scale>
            <uri>model://meshes/physicar/Wheel.dae</uri>
          </mesh>
        </geometry>
      </visual>
    </link>
    <joint name='rear_right_wheel_joint' type='revolute'>
      <pose relative_to='base_footprint'>-0.090000000000000000 -0.080000000000000000 0.0375 0 0 0</pose>
      <parent>base_footprint</parent>
      <child>rear_right_wheel_link</child>
      <axis>
        <xyz>0 1 0</xyz>
        <limit>
          <lower>-inf</lower>          <upper>inf</upper>
        </limit>
        <dynamics>
          <damping>0.5</damping>
          <friction>0.10000000000000001</friction>
          <spring_reference>0</spring_reference>
          <spring_stiffness>0</spring_stiffness>
        </dynamics>
      </axis>
    </joint>
    <link name='rear_right_wheel_link'>
      <pose relative_to='rear_right_wheel_joint'>0 0 0 0 0 0</pose>
      <inertial>
        <pose>0 0 0 0 0 0</pose>
        <mass>0.050000000000000003</mass>
        <inertia>
          <ixx>2.1757291666666671e-05</ixx>
          <ixy>0</ixy>
          <ixz>0</ixz>
          <iyy>3.330625e-05</iyy>
          <iyz>0</iyz>
          <izz>2.1757291666666671e-05</izz>
        </inertia>
      </inertial>
      <collision name='rear_right_wheel_link_collision'>
        <pose>0 0 0 1.5707963267948959 0 0</pose>
        <geometry>
          <cylinder>
            <length>0.035000000000000003</length>
            <radius>0.0375</radius>
          </cylinder>
        </geometry>
        <surface>
          <contact>
            <ode>
              <kp>1000000</kp>
              <kd>100</kd>
              <min_depth>0.001</min_depth>
            </ode>
          </contact>
          <friction>
            <ode>
              <mu>1</mu>
              <mu2>1</mu2>
            </ode>
          </friction>
        </surface>
      </collision>
      <visual name='rear_right_wheel_link_visual'>
        <pose>0 -0.017500000000000002 0 0 0 0</pose>
        <geometry>
          <mesh>
            <scale>1 1 1</scale>
            <uri>model://meshes/physicar/Wheel.dae</uri>
          </mesh>
        </geometry>
      </visual>
    </link>
    <plugin name='gz::sim::systems::AckermannSteering' filename='gz-sim-ackermann-steering-system'>
      <left_joint>front_left_wheel_joint</left_joint>
      <left_joint>rear_left_wheel_joint</left_joint>
      <right_joint>front_right_wheel_joint</right_joint>
      <right_joint>rear_right_wheel_joint</right_joint>
      <left_steering_joint>front_left_steering_joint</left_steering_joint>
      <right_steering_joint>front_right_steering_joint</right_steering_joint>
      <kingpin_width>0.16</kingpin_width>
      <steering_limit>0.436332</steering_limit>
      <wheel_base>0.18</wheel_base>
      <wheel_separation>0.16</wheel_separation>
      <wheel_radius>0.0375</wheel_radius>
      <min_velocity>-3.0</min_velocity>
      <max_velocity>3.0</max_velocity>
      <min_acceleration>-10</min_acceleration>
      <max_acceleration>10</max_acceleration>
      <steer_p_gain>200</steer_p_gain>
      <topic>cmd_vel</topic>
    </plugin>
    <plugin name='gz::sim::systems::OdometryPublisher' filename='gz-sim-odometry-publisher-system'>
      <odom_frame>odom</odom_frame>
      <robot_base_frame>base_footprint</robot_base_frame>
      <odom_topic>odom</odom_topic>
      <dimensions>3</dimensions>
      <odom_publish_frequency>50</odom_publish_frequency>
    </plugin>
    <plugin name='gz::sim::systems::JointPositionController' filename='gz-sim-joint-position-controller-system'>
      <joint_name>camera_pan_joint</joint_name>
      <topic>/camera/pan</topic>
      <p_gain>15</p_gain>
      <i_gain>0</i_gain>
      <d_gain>0.1</d_gain>
      <cmd_max>15</cmd_max>
      <cmd_min>-15</cmd_min>
    </plugin>
    <plugin name='gz::sim::systems::JointPositionController' filename='gz-sim-joint-position-controller-system'>
      <joint_name>camera_tilt_joint</joint_name>
      <topic>/camera/tilt</topic>
      <p_gain>15</p_gain>
      <i_gain>0</i_gain>
      <d_gain>0.1</d_gain>
      <cmd_max>15</cmd_max>
      <cmd_min>-15</cmd_min>
    </plugin>
    <plugin name='gz::sim::systems::JointStatePublisher' filename='gz-sim-joint-state-publisher-system'>
      <topic>joint_states</topic>
      <joint_name>camera_pan_joint</joint_name>
      <joint_name>camera_tilt_joint</joint_name>
      <joint_name>rear_left_wheel_joint</joint_name>
      <joint_name>rear_right_wheel_joint</joint_name>
      <joint_name>front_left_wheel_joint</joint_name>
      <joint_name>front_right_wheel_joint</joint_name>
      <joint_name>front_left_steering_joint</joint_name>
      <joint_name>front_right_steering_joint</joint_name>
    </plugin>
    <frame name='imu_joint' attached_to='base_link'>
      <pose>0 0 0.0275 0 0 0</pose>
    </frame>
    <frame name='imu_link' attached_to='imu_joint'>
      <pose>0 0 0 0 0 0</pose>
    </frame>
    <frame name='lidar_joint' attached_to='base_link'>
      <pose>-0.027 0 0.14550000000000001 0 0 0</pose>
    </frame>
    <frame name='lidar_link' attached_to='lidar_joint'>
      <pose>0 0 0 0 0 0</pose>
    </frame>
    <frame name='base_joint' attached_to='base_footprint'>
      <pose>0 0 0.0375 0 0 0</pose>
    </frame>
    <frame name='base_link' attached_to='base_joint'>
      <pose>0 0 0 0 0 0</pose>
    </frame>
    <frame name='camera_optical_joint' attached_to='camera_link'>
      <pose>0 0 0 -1.5707963267948959 -5.5511151231257827e-17 -1.5707963267948959</pose>
    </frame>
    <frame name='camera_optical_frame' attached_to='camera_optical_joint'>
      <pose>0 0 0 0 0 0</pose>
    </frame>
    <frame name='camera_joint' attached_to='camera_tilt_link'>
      <pose>0.030 0 0.014 0 0 0</pose>
    </frame>
    <frame name='camera_link' attached_to='camera_joint'>
      <pose>0 0 0 0 0 0</pose>
    </frame>
  </model>
</sdf>
